Workbook

Sheet Dashboard Ejecutivo
A2: DATALARIA | EXECUTIVE DECISION PACK - CUADRO DE MANDO ESTRATÉGICO
A3: Diagnóstico cuantitativo en tiempo real para Comité de Dirección (C-Level). Modelo vectorial de decisión.
A5: 1. RESUMEN EJECUTIVO DE PUNTUACIONES CUANTITATIVAS | E5: DISTRIBUCIÓN EN MATRIZ CARTESIANA
B6: Puntuación Total Fortalezas (SF) | C6: ='Evaluación FODA'!F17 -> 4.5 | E6: REORIENTACIÓN / ADAPTACIÓN (Mini-Maxi) X < 0 (Debilidades dominan) Y ≥ 0 (Oportunidades altas) | G6: OFENSIVA / CRECIMIENTO (Maxi-Maxi) X ≥ 0 (Fortalezas dominan) Y ≥ 0 (Oportunidades altas)
B7: Puntuación Total Debilidades (SD) | C7: ='Evaluación FODA'!F32 -> 3.5
B8: Puntuación Total Oportunidades (SO) | C8: ='Evaluación FODA'!F47 -> 4.55
B9: Puntuación Total Amenazas (SA) | C9: ='Evaluación FODA'!F62 -> 3.45
E10: ◄── INTERNO: DEBILIDADES (-X) | FORTALEZAS (+X) ──►
A11: 2. VECTOR DE FUERZA Y POSTURA ESTRATÉGICA DOMINANTE | E11: SUPERVIVENCIA / CONTENCIÓN (Mini-Mini) X < 0 (Debilidades dominan) Y < 0 (Amenazas críticas) | G11: DEFENSIVA / PROTECCIÓN (Maxi-Mini) X ≥ 0 (Fortalezas dominan) Y < 0 (Amenazas críticas)
B12: Posición Interna Neta (X = SF - SD) | C12: =C6-C7 -> 1
B13: Presión Externa Neta (Y = SO - SA) | C13: =C8-C9 -> 1.1
B14: Magnitud del Vector Estratégico (||V||) | C14: =SQRT(C12^2+C13^2) -> 1.4866069
A16: POSTURA ESTRATÉGICA DOMINANTE | E16: ="VECTOR ACTUAL: Coordenadas (" & TEXT(C12,"+0.00;-0.00;0.00") & " , " & TEXT(C13,"+0.00;-0.00;0.00") & ") • Impulso: " & TEXT(C14,"0.00") -> VECTOR ACTUAL: Coordenadas (+1.00 , +1.10) • Impulso: 1.49
A17: =IF(AND(C12>=0, C13>=0), "OFENSIVA / CRECIMIENTO (Maxi-Maxi)", IF(AND(C12>=0, C13<0), "DEFENSIVA / PROTECCIÓN (Maxi-Mini)", IF(AND(C12<0, C13>=0), "REORIENTACIÓN / ADAPTACIÓN (Mini-Maxi)", "SUPERVIVENCIA / CONTENCIÓN (Mini-Mini)"))) -> OFENSIVA / CRECIMIENTO (Maxi-Maxi)
A19: 3. SÍNTESIS ESTRATÉGICA Y RECOMENDACIÓN PARA EL CONSEJO
A20: =IF(AND(C12>=0, C13>=0), "Postura Ofensiva Validada: La organización cuenta con solidez interna superior a sus vulnerabilidades y un entorno externo favorable. Máxima asignación de CAPEX a captura de cuota, innovación agresiva y expansión internacional.", IF(AND(C12>=0, C13<0), "Postura Defensiva: Las capacidades internas son robustas pero el entorno macro y competitivo presenta amenazas críticas. Priorizar blindaje de contratos clave, aseguramiento de márgenes y diversificación de proveedores.", IF(AND(C12<0, C13>=0), "Postura de Reorientación: Existen catalizadores externos extraordinarios que la organización no puede capturar plenamente debido a cuellos de botella internos. Priorizar transformación operativa y reducción de deuda técnica.", "Postura de Supervivencia: Amenazas externas severas combinadas con debilidades críticas internas. Ejecutar plan de contención de costes, desinversión selectiva de activos no core y renegociación de pasivos."))) -> Postura Ofensiva Validada: La organización cuenta con solidez interna superior a sus vulnerabilidades y un entorno externo favorable. Máxima asignación de CAPEX a captura de cuota, innovación agresiva y expansión internacional.

Sheet Evaluación FODA
A2: DATALARIA | EVALUACIÓN CUANTITATIVA FODA
A3: Asignación de pesos relativos (Σ = 100%) y calificación de impacto (1 a 5). Puntuación ponderada calculada dinámicamente. Filas vacías no computan.
A5: 1. FORTALEZAS (Capacidades y Activos Internos Clave)
A6: Código | B6: Factor Estratégico Evaluado (Editable) | C6: Métrica Base / Evidencia Cuantitativa | D6: Peso Relativo (wi) | E6: Impacto (1-5) | F6: Puntuación Ponderada
A7: F01 | B7: Margen operativo bruto superior al sector (+18.4%) | C7: Auditoría Financiera 2025: EBITDA 24.2% vs 17.5% media | D7: 0.3 | E7: 5 | F7: =IF(OR(B7="", D7=""), 0, D7*E7) -> 1.5
A8: F02 | B8: Propiedad Intelectual y patentes de software predictivo | C8: 3 patentes europeas registradas con vigencia > 2035 | D8: 0.25 | E8: 4 | F8: =IF(OR(B8="", D8=""), 0, D8*E8) -> 1
A9: F03 | B9: Retención neta de clientes enterprise (NRR) del 118% | C9: Cohorte 2023-2025: rotación de clientes < 2.1% anual | D9: 0.2 | E9: 5 | F9: =IF(OR(B9="", D9=""), 0, D9*E9) -> 1
A10: F04 | B10: Infraestructura cloud certificada ISO 27001 y ENS Alto | C10: Auditoría de ciberseguridad sin no conformidades | D10: 0.15 | E10: 4 | F10: =IF(OR(B10="", D10=""), 0, D10*E10) -> 0.6
A11: F05 | B11: Equipo de I+D interno con baja rotación de talento (<4%) | C11: Índice eNPS de 74 puntos en encuestas semestrales | D11: 0.1 | E11: 4 | F11: =IF(OR(B11="", D11=""), 0, D11*E11) -> 0.4
A12: F06 | F12: =IF(OR(B12="", D12=""), 0, D12*E12) -> 0
A13: F07 | F13: =IF(OR(B13="", D13=""), 0, D13*E13) -> 0
A14: F08 | F14: =IF(OR(B14="", D14=""), 0, D14*E14) -> 0
A15: F09 | F15: =IF(OR(B15="", D15=""), 0, D15*E15) -> 0
A16: F10 | F16: =IF(OR(B16="", D16=""), 0, D16*E16) -> 0
C17: TOTAL PONDERADO DEL CUADRANTE | D17: =SUM(D7:D16) -> 1 | E17: =IF(COUNTBLANK(D7:D16)=10, "— Sin datos —", IF(ROUND(SUM(D7:D16),2)=1, "✓ 100% Correcto", "⚠ Suma: " & TEXT(SUM(D7:D16),"0.0%") & " (debe sumar 100%)")) -> ✓ 100% Correcto | F17: =SUM(F7:F16) -> 4.5
A20: 2. DEBILIDADES (Vulnerabilidades y Cuellos de Botella Internos)
A21: Código | B21: Factor Estratégico Evaluado (Editable) | C21: Métrica Base / Evidencia Cuantitativa | D21: Peso Relativo (wi) | E21: Impacto (1-5) | F21: Puntuación Ponderada
A22: D01 | B22: Concentración de ingresos en 2 clientes clave (42% facturación) | C22: Riesgo de concentración de cartera auditado | D22: 0.3 | E22: 4 | F22: =IF(OR(B22="", D22=""), 0, D22*E22) -> 1.2
A23: D02 | B23: Lead time de ciclo de ventas enterprise prolongado (8.5 meses) | C23: CRM Salesforce: promedio de oportunidad a cierre | D23: 0.25 | E23: 3 | F23: =IF(OR(B23="", D23=""), 0, D23*E23) -> 0.75
A24: D03 | B24: Dependencia técnica de canal de hardware internacional | C24: Tiempos de entrega de sensores IoT > 14 semanas | D24: 0.2 | E24: 4 | F24: =IF(OR(B24="", D24=""), 0, D24*E24) -> 0.8
A25: D04 | B25: Equipo comercial directo infradimensionado en mercados DACH | C25: Solo 2 ejecutivos para Alemania, Austria y Suiza | D25: 0.15 | E25: 3 | F25: =IF(OR(B25="", D25=""), 0, D25*E25) -> 0.45
A26: D05 | B26: Deuda técnica en módulo legacy de facturación multi-divisa | C26: Horas de mantenimiento correctivo > 18% del sprint | D26: 0.1 | E26: 3 | F26: =IF(OR(B26="", D26=""), 0, D26*E26) -> 0.3
A27: D06 | F27: =IF(OR(B27="", D27=""), 0, D27*E27) -> 0
A28: D07 | F28: =IF(OR(B28="", D28=""), 0, D28*E28) -> 0
A29: D08 | F29: =IF(OR(B29="", D29=""), 0, D29*E29) -> 0
A30: D09 | F30: =IF(OR(B30="", D30=""), 0, D30*E30) -> 0
A31: D10 | F31: =IF(OR(B31="", D31=""), 0, D31*E31) -> 0
C32: TOTAL PONDERADO DEL CUADRANTE | D32: =SUM(D22:D31) -> 1 | E32: =IF(COUNTBLANK(D22:D31)=10, "— Sin datos —", IF(ROUND(SUM(D22:D31),2)=1, "✓ 100% Correcto", "⚠ Suma: " & TEXT(SUM(D22:D31),"0.0%") & " (debe sumar 100%)")) -> ✓ 100% Correcto | F32: =SUM(F22:F31) -> 3.5
A35: 3. OPORTUNIDADES (Tendencias y Vientos de Cola Externos)
A36: Código | B36: Factor Estratégico Evaluado (Editable) | C36: Métrica Base / Evidencia Cuantitativa | D36: Peso Relativo (wi) | E36: Impacto (1-5) | F36: Puntuación Ponderada
A37: O01 | B37: Fondos de digitalización industrial y ayudas NextGen EU | C37: Subvenciones a fondo perdido para automatización | D37: 0.3 | E37: 5 | F37: =IF(OR(B37="", D37=""), 0, D37*E37) -> 1.5
A38: O02 | B38: Demanda acelerada de IA explicable y observabilidad por compliance | C38: Regulación europea EU AI Act en vigor obligatorio | D38: 0.25 | E38: 5 | F38: =IF(OR(B38="", D38=""), 0, D38*E38) -> 1.25
A39: O03 | B39: Consolidación de distribuidores B2B en LatAm (México/Colombia) | C39: Negociación avanzada de acuerdos de distribución | D39: 0.2 | E39: 4 | F39: =IF(OR(B39="", D39=""), 0, D39*E39) -> 0.8
A40: O04 | B40: Obsolescencia de soluciones tradicionales de competidores Tier-2 | C40: Clientes buscando sustitución activa de plataformas | D40: 0.15 | E40: 4 | F40: =IF(OR(B40="", D40=""), 0, D40*E40) -> 0.6
A41: O05 | B41: Alianzas con integradores globales de sistemas (Accenture, Indra) | C41: Interés en incorporar motor predictivo en catálogo | D41: 0.1 | E41: 4 | F41: =IF(OR(B41="", D41=""), 0, D41*E41) -> 0.4
A42: O06 | F42: =IF(OR(B42="", D42=""), 0, D42*E42) -> 0
A43: O07 | F43: =IF(OR(B43="", D43=""), 0, D43*E43) -> 0
A44: O08 | F44: =IF(OR(B44="", D44=""), 0, D44*E44) -> 0
A45: O09 | F45: =IF(OR(B45="", D45=""), 0, D45*E45) -> 0
A46: O10 | F46: =IF(OR(B46="", D46=""), 0, D46*E46) -> 0
...

Sheet Matriz de Cruce
A2: DATALARIA | MATRIZ DE CRUCE CUANTITATIVO (CAME / TOWS)
A3: Evaluación de impacto cruzado (0 = Nulo, 1 = Débil, 2 = Moderado, 3 = Crítico / Sinérgico). Identifica factores catalizadores y vulnerabilidades críticas.
C5: OPORTUNIDADES (O01 - O10) | M5: AMENAZAS (A01 - A10)
A6: ID | B6: FACTORES INTERNOS (FILAS) | C6: O01 | D6: O02 | E6: O03 | F6: O04 | G6: O05 | H6: O06 | I6: O07 | J6: O08 | K6: O09 | L6: O10 | M6: A01 | N6: A02 | O6: A03 | P6: A04 | Q6: A05 | R6: A06 | S6: A07 | T6: A08 | U6: A09 | V6: A10 | W6: Total Fila
A7: FORTALEZAS (F01 - F10)
A8: F01 | B8: =IF('Evaluación FODA'!B7<>"", 'Evaluación FODA'!B7, "F01 [Disponible]") -> Margen operativo bruto superior al sector (+18.4%) | C8: 3 | D8: 3 | E8: 2 | F8: 3 | G8: 2 | H8: 0 | I8: 0 | J8: 0 | K8: 0 | L8: 0 | M8: 2 | N8: 1 | O8: 1 | P8: 3 | Q8: 2 | R8: 0 | S8: 0 | T8: 0 | U8: 0 | V8: 0 | W8: =SUM(C8:V8) -> 22
A9: F02 | B9: =IF('Evaluación FODA'!B8<>"", 'Evaluación FODA'!B8, "F02 [Disponible]") -> Propiedad Intelectual y patentes de software predictivo | C9: 3 | D9: 3 | E9: 1 | F9: 2 | G9: 3 | H9: 0 | I9: 0 | J9: 0 | K9: 0 | L9: 0 | M9: 1 | N9: 2 | O9: 1 | P9: 2 | Q9: 3 | R9: 0 | S9: 0 | T9: 0 | U9: 0 | V9: 0 | W9: =SUM(C9:V9) -> 21
A10: F03 | B10: =IF('Evaluación FODA'!B9<>"", 'Evaluación FODA'!B9, "F03 [Disponible]") -> Retención neta de clientes enterprise (NRR) del 118% | C10: 2 | D10: 3 | E10: 3 | F10: 2 | G10: 2 | H10: 0 | I10: 0 | J10: 0 | K10: 0 | L10: 0 | M10: 2 | N10: 1 | O10: 2 | P10: 2 | Q10: 2 | R10: 0 | S10: 0 | T10: 0 | U10: 0 | V10: 0 | W10: =SUM(C10:V10) -> 21
A11: F04 | B11: =IF('Evaluación FODA'!B10<>"", 'Evaluación FODA'!B10, "F04 [Disponible]") -> Infraestructura cloud certificada ISO 27001 y ENS Alto | C11: 2 | D11: 3 | E11: 2 | F11: 3 | G11: 3 | H11: 0 | I11: 0 | J11: 0 | K11: 0 | L11: 0 | M11: 2 | N11: 1 | O11: 1 | P11: 1 | Q11: 3 | R11: 0 | S11: 0 | T11: 0 | U11: 0 | V11: 0 | W11: =SUM(C11:V11) -> 21
A12: F05 | B12: =IF('Evaluación FODA'!B11<>"", 'Evaluación FODA'!B11, "F05 [Disponible]") -> Equipo de I+D interno con baja rotación de talento (<4%) | C12: 2 | D12: 2 | E12: 1 | F12: 1 | G12: 2 | H12: 0 | I12: 0 | J12: 0 | K12: 0 | L12: 0 | M12: 1 | N12: 3 | O12: 1 | P12: 2 | Q12: 1 | R12: 0 | S12: 0 | T12: 0 | U12: 0 | V12: 0 | W12: =SUM(C12:V12) -> 16
A13: F06 | B13: =IF('Evaluación FODA'!B12<>"", 'Evaluación FODA'!B12, "F06 [Disponible]") -> F06 [Disponible] | C13: 0 | D13: 0 | E13: 0 | F13: 0 | G13: 0 | H13: 0 | I13: 0 | J13: 0 | K13: 0 | L13: 0 | M13: 0 | N13: 0 | O13: 0 | P13: 0 | Q13: 0 | R13: 0 | S13: 0 | T13: 0 | U13: 0 | V13: 0 | W13: =SUM(C13:V13) -> 0
A14: F07 | B14: =IF('Evaluación FODA'!B13<>"", 'Evaluación FODA'!B13, "F07 [Disponible]") -> F07 [Disponible] | C14: 0 | D14: 0 | E14: 0 | F14: 0 | G14: 0 | H14: 0 | I14: 0 | J14: 0 | K14: 0 | L14: 0 | M14: 0 | N14: 0 | O14: 0 | P14: 0 | Q14: 0 | R14: 0 | S14: 0 | T14: 0 | U14: 0 | V14: 0 | W14: =SUM(C14:V14) -> 0
A15: F08 | B15: =IF('Evaluación FODA'!B14<>"", 'Evaluación FODA'!B14, "F08 [Disponible]") -> F08 [Disponible] | C15: 0 | D15: 0 | E15: 0 | F15: 0 | G15: 0 | H15: 0 | I15: 0 | J15: 0 | K15: 0 | L15: 0 | M15: 0 | N15: 0 | O15: 0 | P15: 0 | Q15: 0 | R15: 0 | S15: 0 | T15: 0 | U15: 0 | V15: 0 | W15: =SUM(C15:V15) -> 0
A16: F09 | B16: =IF('Evaluación FODA'!B15<>"", 'Evaluación FODA'!B15, "F09 [Disponible]") -> F09 [Disponible] | C16: 0 | D16: 0 | E16: 0 | F16: 0 | G16: 0 | H16: 0 | I16: 0 | J16: 0 | K16: 0 | L16: 0 | M16: 0 | N16: 0 | O16: 0 | P16: 0 | Q16: 0 | R16: 0 | S16: 0 | T16: 0 | U16: 0 | V16: 0 | W16: =SUM(C16:V16) -> 0
A17: F10 | B17: =IF('Evaluación FODA'!B16<>"", 'Evaluación FODA'!B16, "F10 [Disponible]") -> F10 [Disponible] | C17: 0 | D17: 0 | E17: 0 | F17: 0 | G17: 0 | H17: 0 | I17: 0 | J17: 0 | K17: 0 | L17: 0 | M17: 0 | N17: 0 | O17: 0 | P17: 0 | Q17: 0 | R17: 0 | S17: 0 | T17: 0 | U17: 0 | V17: 0 | W17: =SUM(C17:V17) -> 0
A18: DEBILIDADES (D01 - D10)
A19: D01 | B19: =IF('Evaluación FODA'!B21<>"", 'Evaluación FODA'!B21, "D01 [Disponible]") -> Factor Estratégico Evaluado (Editable) | C19: 1 | D19: 1 | E19: 3 | F19: 2 | G19: 1 | H19: 0 | I19: 0 | J19: 0 | K19: 0 | L19: 0 | M19: 3 | N19: 1 | O19: 3 | P19: 3 | Q19: 2 | R19: 0 | S19: 0 | T19: 0 | U19: 0 | V19: 0 | W19: =SUM(C19:V19) -> 20
A20: D02 | B20: =IF('Evaluación FODA'!B22<>"", 'Evaluación FODA'!B22, "D02 [Disponible]") -> Concentración de ingresos en 2 clientes clave (42% facturación) | C20: 1 | D20: 2 | E20: 1 | F20: 1 | G20: 2 | H20: 0 | I20: 0 | J20: 0 | K20: 0 | L20: 0 | M20: 3 | N20: 2 | O20: 2 | P20: 3 | Q20: 1 | R20: 0 | S20: 0 | T20: 0 | U20: 0 | V20: 0 | W20: =SUM(C20:V20) -> 18
A21: D03 | B21: =IF('Evaluación FODA'!B23<>"", 'Evaluación FODA'!B23, "D03 [Disponible]") -> Lead time de ciclo de ventas enterprise prolongado (8.5 meses) | C21: 1 | D21: 1 | E21: 2 | F21: 1 | G21: 1 | H21: 0 | I21: 0 | J21: 0 | K21: 0 | L21: 0 | M21: 3 | N21: 2 | O21: 3 | P21: 2 | Q21: 2 | R21: 0 | S21: 0 | T21: 0 | U21: 0 | V21: 0 | W21: =SUM(C21:V21) -> 18
A22: D04 | B22: =IF('Evaluación FODA'!B24<>"", 'Evaluación FODA'!B24, "D04 [Disponible]") -> Dependencia técnica de canal de hardware internacional | C22: 1 | D22: 1 | E22: 1 | F22: 2 | G22: 1 | H22: 0 | I22: 0 | J22: 0 | K22: 0 | L22: 0 | M22: 2 | N22: 1 | O22: 2 | P22: 2 | Q22: 1 | R22: 0 | S22: 0 | T22: 0 | U22: 0 | V22: 0 | W22: =SUM(C22:V22) -> 14
A23: D05 | B23: =IF('Evaluación FODA'!B25<>"", 'Evaluación FODA'!B25, "D05 [Disponible]") -> Equipo comercial directo infradimensionado en mercados DACH | C23: 1 | D23: 2 | E23: 1 | F23: 1 | G23: 1 | H23: 0 | I23: 0 | J23: 0 | K23: 0 | L23: 0 | M23: 1 | N23: 2 | O23: 1 | P23: 1 | Q23: 3 | R23: 0 | S23: 0 | T23: 0 | U23: 0 | V23: 0 | W23: =SUM(C23:V23) -> 14
A24: D06 | B24: =IF('Evaluación FODA'!B26<>"", 'Evaluación FODA'!B26, "D06 [Disponible]") -> Deuda técnica en módulo legacy de facturación multi-divisa | C24: 0 | D24: 0 | E24: 0 | F24: 0 | G24: 0 | H24: 0 | I24: 0 | J24: 0 | K24: 0 | L24: 0 | M24: 0 | N24: 0 | O24: 0 | P24: 0 | Q24: 0 | R24: 0 | S24: 0 | T24: 0 | U24: 0 | V24: 0 | W24: =SUM(C24:V24) -> 0
A25: D07 | B25: =IF('Evaluación FODA'!B27<>"", 'Evaluación FODA'!B27, "D07 [Disponible]") -> D07 [Disponible] | C25: 0 | D25: 0 | E25: 0 | F25: 0 | G25: 0 | H25: 0 | I25: 0 | J25: 0 | K25: 0 | L25: 0 | M25: 0 | N25: 0 | O25: 0 | P25: 0 | Q25: 0 | R25: 0 | S25: 0 | T25: 0 | U25: 0 | V25: 0 | W25: =SUM(C25:V25) -> 0
A26: D08 | B26: =IF('Evaluación FODA'!B28<>"", 'Evaluación FODA'!B28, "D08 [Disponible]") -> D08 [Disponible] | C26: 0 | D26: 0 | E26: 0 | F26: 0 | G26: 0 | H26: 0 | I26: 0 | J26: 0 | K26: 0 | L26: 0 | M26: 0 | N26: 0 | O26: 0 | P26: 0 | Q26: 0 | R26: 0 | S26: 0 | T26: 0 | U26: 0 | V26: 0 | W26: =SUM(C26:V26) -> 0
A27: D09 | B27: =IF('Evaluación FODA'!B29<>"", 'Evaluación FODA'!B29, "D09 [Disponible]") -> D09 [Disponible] | C27: 0 | D27: 0 | E27: 0 | F27: 0 | G27: 0 | H27: 0 | I27: 0 | J27: 0 | K27: 0 | L27: 0 | M27: 0 | N27: 0 | O27: 0 | P27: 0 | Q27: 0 | R27: 0 | S27: 0 | T27: 0 | U27: 0 | V27: 0 | W27: =SUM(C27:V27) -> 0
A28: D10 | B28: =IF('Evaluación FODA'!B30<>"", 'Evaluación FODA'!B30, "D10 [Disponible]") -> D10 [Disponible] | C28: 0 | D28: 0 | E28: 0 | F28: 0 | G28: 0 | H28: 0 | I28: 0 | J28: 0 | K28: 0 | L28: 0 | M28: 0 | N28: 0 | O28: 0 | P28: 0 | Q28: 0 | R28: 0 | S28: 0 | T28: 0 | U28: 0 | V28: 0 | W28: =SUM(C28:V28) -> 0
B29: Total Columna | C29: =SUM(C8:C17)+SUM(C19:C28) -> 17 | D29: =SUM(D8:D17)+SUM(D19:D28) -> 21 | E29: =SUM(E8:E17)+SUM(E19:E28) -> 17 | F29: =SUM(F8:F17)+SUM(F19:F28) -> 18 | G29: =SUM(G8:G17)+SUM(G19:G28) -> 18 | H29: =SUM(H8:H17)+SUM(H19:H28) -> 0 | I29: =SUM(I8:I17)+SUM(I19:I28) -> 0 | J29: =SUM(J8:J17)+SUM(J19:J28) -> 0 | ... W29: =SUM(W8:W17)+SUM(W19:W28) -> 185
B31: Sinergia Ofensiva Total (F x O) | H31: Impacto Defensivo Total (F x A) | N31: Cuellos de Botella (D x O) | T31: Vulnerabilidad Crítica (D x A)
B32: =SUM(C8:L17) -> 58 | H32: =SUM(M8:V17) -> 43 | N32: =SUM(C19:L28) -> 33 | T32: =SUM(M19:V28) -> 51

Sheet Plan CAME
A2: DATALARIA | PLAN ESTRATÉGICO DE ACCIÓN CAME (C-LEVEL ROADMAP)
A3: Traducción operativa de la matriz de decisión en iniciativas de inversión con responsable C-Level, plazos y dotación financiera P&L.
A5: 1. CORREGIR DEBILIDADES (Iniciativas de Reorientación / WO)
A6: ID Acción | B6: Factor Clave | C6: Iniciativa Estratégica Concreta | D6: Owner (C-Level) | E6: Plazo | F6: CAPEX (€) | G6: OPEX (€) | H6: KPI de Impacto en P&L | I6: Estado
A7: CAME-C01 | B7: D01 + O03 | C7: Plan de Diversificación Comercial: Programa de canal en LatAm para reducir concentración a < 25% | D7: Chief Commercial Officer | E7: Q2-Q4 | F7: 45000 | G7: 60000 | H7: Concentración top-2 < 25% ARR | I7: Aprobado
A8: CAME-C02 | B8: D02 + O05 | C8: Automatización de ciclo comercial con integradores globales para acortar lead time a 5 meses | D8: VP Sales Enterprise | E8: Q1-Q3 | F8: 25000 | G8: 35000 | H8: Lead time ventas ≤ 5.2 meses | I8: Aprobado
A9: CAME-C03 | B9: D05 + O02 | C9: Refactorización del motor de facturación multi-divisa hacia microservicios cloud | D9: Chief Technology Officer | E9: Q2-Q3 | F9: 40000 | G9: 15000 | H9: Deuda técnica sprint < 6% | I9: En Revisión
A10: TOTAL INVERSIÓN SECCIÓN (C) | F10: =SUM(F7:F9) -> 110000 | G10: =SUM(G7:G9) -> 110000
A12: 2. AFRONTAR AMENAZAS (Iniciativas Defensivas y Salvaguardas / ST)
A13: ID Acción | B13: Factor Clave | C13: Iniciativa Estratégica Concreta | D13: Owner (C-Level) | E13: Plazo | F13: CAPEX (€) | G13: OPEX (€) | H13: KPI de Impacto en P&L | I13: Estado
A14: CAME-A01 | B14: F01 + A01 | C14: Blindaje contractual plurianual con clientes clave con cláusula de fidelización | D14: Chief Executive Officer | E14: Q1-Q2 | F14: 10000 | G14: 20000 | H14: Churn de clientes < 1.5% | I14: Aprobado
A15: CAME-A02 | B15: F04 + A05 | C15: Certificación anticipada en directiva NIS2 y auditoría de resiliencia operativa DORA | D15: Chief Information Security Officer | E15: Q2-Q3 | F15: 35000 | G15: 15000 | H15: 100% cumplimiento normativo | I15: Aprobado
A16: TOTAL INVERSIÓN SECCIÓN (A) | F16: =SUM(F14:F15) -> 45000 | G16: =SUM(G14:G15) -> 35000
A18: 3. MANTENER FORTALEZAS (Iniciativas de Preservación de Moat / Moat Defense)
A19: ID Acción | B19: Factor Clave | C19: Iniciativa Estratégica Concreta | D19: Owner (C-Level) | E19: Plazo | F19: CAPEX (€) | G19: OPEX (€) | H19: KPI de Impacto en P&L | I19: Estado
A20: CAME-M01 | B20: F02 + O02 | C20: Extensión de patentes de algoritmos a jurisdicciones asiáticas y protección de IP | D20: Head of Legal & IP | E20: Q3-Q4 | F20: 30000 | G20: 10000 | H20: 2 nuevas patentes concedidas | I20: Propuesto
A21: CAME-M02 | B21: F05 + A02 | C21: Plan de retención de talento clave de I+D (Phantom Shares y plan de carrera técnica) | D21: Chief People Officer | E21: Q1-Q4 | F21: 0 | G21: 45000 | H21: Rotación voluntaria < 3% | I21: Aprobado
A22: TOTAL INVERSIÓN SECCIÓN (M) | F22: =SUM(F20:F21) -> 30000 | G22: =SUM(G20:G21) -> 55000
A24: 4. EXPLOTAR OPORTUNIDADES (Iniciativas Ofensivas de Crecimiento / SO)
A25: ID Acción | B25: Factor Clave | C25: Iniciativa Estratégica Concreta | D25: Owner (C-Level) | E25: Plazo | F25: CAPEX (€) | G25: OPEX (€) | H25: KPI de Impacto en P&L | I25: Estado
A26: CAME-E01 | B26: F01 + O01 | C26: Aceleración del despliegue del módulo SaaS subvencionado por NextGen en 40 factorías | D26: Chief Operating Officer | E26: Q1-Q3 | F26: 65000 | G26: 40000 | H26: +1.2M € ARR adicional | I26: Aprobado
A27: CAME-E02 | B27: F03 + O05 | C27: Acuerdo de co-selling con consultora global (Tier-1) para inclusión en licitaciones | D27: Chief Commercial Officer | E27: Q2-Q4 | F27: 20000 | G27: 30000 | H27: +8 nuevos clientes Tier-1 | I27: Aprobado
A28: TOTAL INVERSIÓN SECCIÓN (E) | F28: =SUM(F26:F27) -> 85000 | G28: =SUM(G26:G27) -> 70000
A30: PRESUPUESTO TOTAL PLAN CAME (CAPEX + OPEX) | F30: =F10+F16+F22+F28 -> 270000 | G30: =G10+G16+G22+G28 -> 270000 | H30: =F30+G30 -> 540000
