Workbook

Sheet Executive Dashboard
A2: DATALARIA | EXECUTIVE DECISION PACK - STRATEGIC DASHBOARD
A3: Real-time quantitative C-Level diagnosis for Board meetings. Vector-based decision modeling.
A5: 1. EXECUTIVE SUMMARY OF QUANTITATIVE SCORES | E5: CARTESIAN MATRIX POSITIONING
B6: Total Strengths Score (SS) | C6: ='SWOT Weighted Assessment'!F17 | E6: REORIENTATION / TURNAROUND (Mini-Maxi) X < 0 (Weaknesses dominate) Y ≥ 0 (High opportunities) | G6: OFFENSIVE / EXPANSION (Maxi-Maxi) X ≥ 0 (Strengths dominate) Y ≥ 0 (High opportunities)
B7: Total Weaknesses Score (SW) | C7: ='SWOT Weighted Assessment'!F32
B8: Total Opportunities Score (SO) | C8: ='SWOT Weighted Assessment'!F47
B9: Total Threats Score (ST) | C9: ='SWOT Weighted Assessment'!F62
E10: ◄── INTERNAL: WEAKNESSES (-X) | STRENGTHS (+X) ──►
A11: 2. STRATEGIC FORCE VECTOR & DOMINANT POSTURE | E11: SURVIVAL / RESTRUCTURING (Mini-Mini) X < 0 (Weaknesses dominate) Y < 0 (Critical threats) | G11: DEFENSIVE / FORTRESS (Maxi-Mini) X ≥ 0 (Strengths dominate) Y < 0 (Critical threats)
B12: Net Internal Position (X = SS - SW) | C12: =C6-C7
B13: Net External Pressure (Y = SO - ST) | C13: =C8-C9
B14: Strategic Vector Magnitude (||V||) | C14: =SQRT(C12^2+C13^2)
A16: DOMINANT STRATEGIC POSTURE | E16: ="CURRENT VECTOR: Coordinates (" & TEXT(C12,"+0.00;-0.00;0.00") & " , " & TEXT(C13,"+0.00;-0.00;0.00") & ") • Momentum: " & TEXT(C14,"0.00")
A17: =IF(AND(C12>=0, C13>=0), "OFFENSIVE / EXPANSION (Maxi-Maxi)", IF(AND(C12>=0, C13<0), "DEFENSIVE / FORTRESS (Maxi-Mini)", IF(AND(C12<0, C13>=0), "REORIENTATION / TURNAROUND (Mini-Maxi)", "SURVIVAL / RESTRUCTURING (Mini-Mini)")))
A19: 3. EXECUTIVE BOARD SYNTHESIS & STRATEGIC RECOMMENDATION
A20: =IF(AND(C12>=0, C13>=0), "Offensive Posture Validated: Internal strengths significantly outpace weaknesses within a receptive external environment. Direct maximum capital allocation to market share capture, aggressive R&D, and global scaling.", IF(AND(C12>=0, C13<0), "Defensive Posture: Internal competencies remain strong, but macro headwinds and competitive threats are severe. Prioritize contractual moat building, margin defense, and supplier de-risking.", IF(AND(C12<0, C13>=0), "Reorientation Posture: High external market tailwinds exist, yet internal bottlenecks prevent full value capture. Expedite operational restructuring, talent realignment, and technical debt elimination.", "Survival Posture: Critical external threats compound severe internal vulnerabilities. Enforce strict OPEX containment, divest non-core assets, and restructure liabilities to preserve enterprise solvency.")))

Sheet SWOT Weighted Assessment
A2: DATALARIA | QUANTITATIVE SWOT ASSESSMENT
A3: Relative weight allocation (Σ = 100%) and impact rating (1 to 5). Weighted scores calculate dynamically. Blank rows safely ignored.
A5: 1. STRENGTHS (Core Internal Capabilities & Strategic Assets)
A6: Code | B6: Strategic Factor Evaluated (Editable) | C6: Baseline Metric / Quantitative Evidence | D6: Weight (wi) | E6: Impact (1-5) | F6: Weighted Score
A7: S01 | B7: Superior operating gross margin vs sector (+18.4%) | C7: 2025 Financial Audit: EBITDA 24.2% vs 17.5% peer average | D7: 0.3 | E7: 5 | F7: =IF(OR(B7="", D7=""), 0, D7*E7)
A8: S02 | B8: Proprietary IP and predictive software patents | C8: 3 European and US patents granted through 2036 | D8: 0.25 | E8: 4 | F8: =IF(OR(B8="", D8=""), 0, D8*E8)
A9: S03 | B9: Enterprise Net Retention Rate (NRR) of 118% | C9: 2023-2025 cohort: annual logo churn < 2.1% | D9: 0.2 | E9: 5 | F9: =IF(OR(B9="", D9=""), 0, D9*E9)
A10: S04 | B10: ISO 27001 and SOC 2 Type II certified cloud infrastructure | C10: Zero non-conformities in annual security audit | D10: 0.15 | E10: 4 | F10: =IF(OR(B10="", D10=""), 0, D10*E10)
A11: S05 | B11: High-retention internal R&D talent (turnover < 4%) | C11: eNPS score of 74 points in bi-annual team survey | D11: 0.1 | E11: 4 | F11: =IF(OR(B11="", D11=""), 0, D11*E11)
A12: S06 | F12: =IF(OR(B12="", D12=""), 0, D12*E12)
A13: S07 | F13: =IF(OR(B13="", D13=""), 0, D13*E13)
A14: S08 | F14: =IF(OR(B14="", D14=""), 0, D14*E14)
A15: S09 | F15: =IF(OR(B15="", D15=""), 0, D15*E15)
A16: S10 | F16: =IF(OR(B16="", D16=""), 0, D16*E16)
C17: TOTAL WEIGHTED SCORE | D17: =SUM(D7:D16) | E17: =IF(COUNTBLANK(D7:D16)=10, "— No data —", IF(ROUND(SUM(D7:D16),2)=1, "✓ 100% Valid", "⚠ Sum: " & TEXT(SUM(D7:D16),"0.0%") & " (must equal 100%)")) | F17: =SUM(F7:F16)
A20: 2. WEAKNESSES (Internal Vulnerabilities & Operational Bottlenecks)
A21: Code | B21: Strategic Factor Evaluated (Editable) | C21: Baseline Metric / Quantitative Evidence | D21: Weight (wi) | E21: Impact (1-5) | F21: Weighted Score
A22: W01 | B22: Revenue concentration in 2 key enterprise clients (42% ARR) | C22: High single-client dependency identified in audit | D22: 0.3 | E22: 4 | F22: =IF(OR(B22="", D22=""), 0, D22*E22)
A23: W02 | B23: Long enterprise sales cycle duration (8.5 months average) | C23: Salesforce CRM: qualified pipeline to deal close | D23: 0.25 | E23: 3 | F23: =IF(OR(B23="", D23=""), 0, D23*E23)
A24: W03 | B24: Supply chain dependency on international IoT hardware vendors | C24: Sensor delivery lead times currently > 14 weeks | D24: 0.2 | E24: 4 | F24: =IF(OR(B24="", D24=""), 0, D24*E24)
A25: W04 | B25: Undersized direct commercial sales force in DACH markets | C25: Only 2 account executives covering Germany/Switzerland | D25: 0.15 | E25: 3 | F25: =IF(OR(B25="", D25=""), 0, D25*E25)
A26: W05 | B26: Technical debt in legacy multi-currency billing engine | C26: Maintenance hours > 18% of engineering sprint capacity | D26: 0.1 | E26: 3 | F26: =IF(OR(B26="", D26=""), 0, D26*E26)
A27: W06 | F27: =IF(OR(B27="", D27=""), 0, D27*E27)
A28: W07 | F28: =IF(OR(B28="", D28=""), 0, D28*E28)
A29: W08 | F29: =IF(OR(B29="", D29=""), 0, D29*E29)
A30: W09 | F30: =IF(OR(B30="", D30=""), 0, D30*E30)
A31: W10 | F31: =IF(OR(B31="", D31=""), 0, D31*E31)
C32: TOTAL WEIGHTED SCORE | D32: =SUM(D22:D31) | E32: =IF(COUNTBLANK(D22:D31)=10, "— No data —", IF(ROUND(SUM(D22:D31),2)=1, "✓ 100% Valid", "⚠ Sum: " & TEXT(SUM(D22:D31),"0.0%") & " (must equal 100%)")) | F32: =SUM(F22:F31)
A35: 3. OPPORTUNITIES (External Tailwinds & Emerging Market Spaces)
A36: Code | B36: Strategic Factor Evaluated (Editable) | C36: Baseline Metric / Quantitative Evidence | D36: Weight (wi) | E36: Impact (1-5) | F36: Weighted Score
A37: O01 | B37: Industrial digital transformation & automation capital subsidies | C37: Non-repayable public capital programs for smart factories | D37: 0.3 | E37: 5 | F37: =IF(OR(B37="", D37=""), 0, D37*E37)
A38: O02 | B38: Surging compliance demand for explainable AI & observability | C38: EU AI Act and international governance frameworks | D38: 0.25 | E38: 5 | F38: =IF(OR(B38="", D38=""), 0, D38*E38)
A39: O03 | B39: B2B distributor network consolidation in LatAm & US Sunbelt | C39: Advanced negotiations for master distribution partnership | D39: 0.2 | E39: 4 | F39: =IF(OR(B39="", D39=""), 0, D39*E39)
A40: O04 | B40: Obsolescence and vendor fatigue among Tier-2 legacy solutions | C40: Enterprise RFP wave seeking modern cloud alternatives | D40: 0.15 | E40: 4 | F40: =IF(OR(B40="", D40=""), 0, D40*E40)
A41: O05 | B41: Co-sell partnerships with Tier-1 System Integrators | C41: Interest from leading consultancies to package our IP | D41: 0.1 | E41: 4 | F41: =IF(OR(B41="", D41=""), 0, D41*E41)
A42: O06 | F42: =IF(OR(B42="", D42=""), 0, D42*E42)
A43: O07 | F43: =IF(OR(B43="", D43=""), 0, D43*E43)
A44: O08 | F44: =IF(OR(B44="", D44=""), 0, D44*E44)
A45: O09 | F45: =IF(OR(B45="", D45=""), 0, D45*E45)
A46: O10 | F46: =IF(OR(B46="", D46=""), 0, D46*E46)
...

Sheet TOWS Cross-Impact Matrix
A2: DATALARIA | TOWS QUANTITATIVE CROSS-IMPACT MATRIX
A3: Cross-impact scale (0 = None, 1 = Low, 2 = Moderate, 3 = Critical / Synergistic). Identifies primary catalysts and acute operational vulnerabilities.
C5: OPPORTUNITIES (O01 - O10) | M5: THREATS (T01 - T10)
A6: ID | B6: INTERNAL FACTORS (ROWS) | C6: O01 | D6: O02 | E6: O03 | F6: O04 | G6: O05 | H6: O06 | I6: O07 | J6: O08 | K6: O09 | L6: O10 | M6: T01 | N6: T02 | O6: T03 | P6: T04 | Q6: T05 | R6: T06 | S6: T07 | T6: T08 | U6: T09 | V6: T10 | W6: Row Total
A7: STRENGTHS (S01 - S10)
A8: S01 | B8: =IF('SWOT Weighted Assessment'!B7<>"", 'SWOT Weighted Assessment'!B7, "S01 [Disponible]") | C8: 3 | D8: 3 | E8: 2 | F8: 3 | G8: 2 | H8: 0 | I8: 0 | J8: 0 | K8: 0 | L8: 0 | M8: 2 | N8: 1 | O8: 1 | P8: 3 | Q8: 2 | R8: 0 | S8: 0 | T8: 0 | U8: 0 | V8: 0 | W8: =SUM(C8:V8)
A9: S02 | B9: =IF('SWOT Weighted Assessment'!B8<>"", 'SWOT Weighted Assessment'!B8, "S02 [Disponible]") | C9: 3 | D9: 3 | E9: 1 | F9: 2 | G9: 3 | H9: 0 | I9: 0 | J9: 0 | K9: 0 | L9: 0 | M9: 1 | N9: 2 | O9: 1 | P9: 2 | Q9: 3 | R9: 0 | S9: 0 | T9: 0 | U9: 0 | V9: 0 | W9: =SUM(C9:V9)
A10: S03 | B10: =IF('SWOT Weighted Assessment'!B9<>"", 'SWOT Weighted Assessment'!B9, "S03 [Disponible]") | C10: 2 | D10: 3 | E10: 3 | F10: 2 | G10: 2 | H10: 0 | I10: 0 | J10: 0 | K10: 0 | L10: 0 | M10: 2 | N10: 1 | O10: 2 | P10: 2 | Q10: 2 | R10: 0 | S10: 0 | T10: 0 | U10: 0 | V10: 0 | W10: =SUM(C10:V10)
A11: S04 | B11: =IF('SWOT Weighted Assessment'!B10<>"", 'SWOT Weighted Assessment'!B10, "S04 [Disponible]") | C11: 2 | D11: 3 | E11: 2 | F11: 3 | G11: 3 | H11: 0 | I11: 0 | J11: 0 | K11: 0 | L11: 0 | M11: 2 | N11: 1 | O11: 1 | P11: 1 | Q11: 3 | R11: 0 | S11: 0 | T11: 0 | U11: 0 | V11: 0 | W11: =SUM(C11:V11)
A12: S05 | B12: =IF('SWOT Weighted Assessment'!B11<>"", 'SWOT Weighted Assessment'!B11, "S05 [Disponible]") | C12: 2 | D12: 2 | E12: 1 | F12: 1 | G12: 2 | H12: 0 | I12: 0 | J12: 0 | K12: 0 | L12: 0 | M12: 1 | N12: 3 | O12: 1 | P12: 2 | Q12: 1 | R12: 0 | S12: 0 | T12: 0 | U12: 0 | V12: 0 | W12: =SUM(C12:V12)
A13: S06 | B13: =IF('SWOT Weighted Assessment'!B12<>"", 'SWOT Weighted Assessment'!B12, "S06 [Disponible]") | C13: 0 | D13: 0 | E13: 0 | F13: 0 | G13: 0 | H13: 0 | I13: 0 | J13: 0 | K13: 0 | L13: 0 | M13: 0 | N13: 0 | O13: 0 | P13: 0 | Q13: 0 | R13: 0 | S13: 0 | T13: 0 | U13: 0 | V13: 0 | W13: =SUM(C13:V13)
A14: S07 | B14: =IF('SWOT Weighted Assessment'!B13<>"", 'SWOT Weighted Assessment'!B13, "S07 [Disponible]") | C14: 0 | D14: 0 | E14: 0 | F14: 0 | G14: 0 | H14: 0 | I14: 0 | J14: 0 | K14: 0 | L14: 0 | M14: 0 | N14: 0 | O14: 0 | P14: 0 | Q14: 0 | R14: 0 | S14: 0 | T14: 0 | U14: 0 | V14: 0 | W14: =SUM(C14:V14)
A15: S08 | B15: =IF('SWOT Weighted Assessment'!B14<>"", 'SWOT Weighted Assessment'!B14, "S08 [Disponible]") | C15: 0 | D15: 0 | E15: 0 | F15: 0 | G15: 0 | H15: 0 | I15: 0 | J15: 0 | K15: 0 | L15: 0 | M15: 0 | N15: 0 | O15: 0 | P15: 0 | Q15: 0 | R15: 0 | S15: 0 | T15: 0 | U15: 0 | V15: 0 | W15: =SUM(C15:V15)
A16: S09 | B16: =IF('SWOT Weighted Assessment'!B15<>"", 'SWOT Weighted Assessment'!B15, "S09 [Disponible]") | C16: 0 | D16: 0 | E16: 0 | F16: 0 | G16: 0 | H16: 0 | I16: 0 | J16: 0 | K16: 0 | L16: 0 | M16: 0 | N16: 0 | O16: 0 | P16: 0 | Q16: 0 | R16: 0 | S16: 0 | T16: 0 | U16: 0 | V16: 0 | W16: =SUM(C16:V16)
A17: S10 | B17: =IF('SWOT Weighted Assessment'!B16<>"", 'SWOT Weighted Assessment'!B16, "S10 [Disponible]") | C17: 0 | D17: 0 | E17: 0 | F17: 0 | G17: 0 | H17: 0 | I17: 0 | J17: 0 | K17: 0 | L17: 0 | M17: 0 | N17: 0 | O17: 0 | P17: 0 | Q17: 0 | R17: 0 | S17: 0 | T17: 0 | U17: 0 | V17: 0 | W17: =SUM(C17:V17)
A18: WEAKNESSES (W01 - W10)
A19: W01 | B19: =IF('SWOT Weighted Assessment'!B21<>"", 'SWOT Weighted Assessment'!B21, "W01 [Disponible]") | C19: 1 | D19: 1 | E19: 3 | F19: 2 | G19: 1 | H19: 0 | I19: 0 | J19: 0 | K19: 0 | L19: 0 | M19: 3 | N19: 1 | O19: 3 | P19: 3 | Q19: 2 | R19: 0 | S19: 0 | T19: 0 | U19: 0 | V19: 0 | W19: =SUM(C19:V19)
A20: W02 | B20: =IF('SWOT Weighted Assessment'!B22<>"", 'SWOT Weighted Assessment'!B22, "W02 [Disponible]") | C20: 1 | D20: 2 | E20: 1 | F20: 1 | G20: 2 | H20: 0 | I20: 0 | J20: 0 | K20: 0 | L20: 0 | M20: 3 | N20: 2 | O20: 2 | P20: 3 | Q20: 1 | R20: 0 | S20: 0 | T20: 0 | U20: 0 | V20: 0 | W20: =SUM(C20:V20)
A21: W03 | B21: =IF('SWOT Weighted Assessment'!B23<>"", 'SWOT Weighted Assessment'!B23, "W03 [Disponible]") | C21: 1 | D21: 1 | E21: 2 | F21: 1 | G21: 1 | H21: 0 | I21: 0 | J21: 0 | K21: 0 | L21: 0 | M21: 3 | N21: 2 | O21: 3 | P21: 2 | Q21: 2 | R21: 0 | S21: 0 | T21: 0 | U21: 0 | V21: 0 | W21: =SUM(C21:V21)
A22: W04 | B22: =IF('SWOT Weighted Assessment'!B24<>"", 'SWOT Weighted Assessment'!B24, "W04 [Disponible]") | C22: 1 | D22: 1 | E22: 1 | F22: 2 | G22: 1 | H22: 0 | I22: 0 | J22: 0 | K22: 0 | L22: 0 | M22: 2 | N22: 1 | O22: 2 | P22: 2 | Q22: 1 | R22: 0 | S22: 0 | T22: 0 | U22: 0 | V22: 0 | W22: =SUM(C22:V22)
A23: W05 | B23: =IF('SWOT Weighted Assessment'!B25<>"", 'SWOT Weighted Assessment'!B25, "W05 [Disponible]") | C23: 1 | D23: 2 | E23: 1 | F23: 1 | G23: 1 | H23: 0 | I23: 0 | J23: 0 | K23: 0 | L23: 0 | M23: 1 | N23: 2 | O23: 1 | P23: 1 | Q23: 3 | R23: 0 | S23: 0 | T23: 0 | U23: 0 | V23: 0 | W23: =SUM(C23:V23)
A24: W06 | B24: =IF('SWOT Weighted Assessment'!B26<>"", 'SWOT Weighted Assessment'!B26, "W06 [Disponible]") | C24: 0 | D24: 0 | E24: 0 | F24: 0 | G24: 0 | H24: 0 | I24: 0 | J24: 0 | K24: 0 | L24: 0 | M24: 0 | N24: 0 | O24: 0 | P24: 0 | Q24: 0 | R24: 0 | S24: 0 | T24: 0 | U24: 0 | V24: 0 | W24: =SUM(C24:V24)
A25: W07 | B25: =IF('SWOT Weighted Assessment'!B27<>"", 'SWOT Weighted Assessment'!B27, "W07 [Disponible]") | C25: 0 | D25: 0 | E25: 0 | F25: 0 | G25: 0 | H25: 0 | I25: 0 | J25: 0 | K25: 0 | L25: 0 | M25: 0 | N25: 0 | O25: 0 | P25: 0 | Q25: 0 | R25: 0 | S25: 0 | T25: 0 | U25: 0 | V25: 0 | W25: =SUM(C25:V25)
A26: W08 | B26: =IF('SWOT Weighted Assessment'!B28<>"", 'SWOT Weighted Assessment'!B28, "W08 [Disponible]") | C26: 0 | D26: 0 | E26: 0 | F26: 0 | G26: 0 | H26: 0 | I26: 0 | J26: 0 | K26: 0 | L26: 0 | M26: 0 | N26: 0 | O26: 0 | P26: 0 | Q26: 0 | R26: 0 | S26: 0 | T26: 0 | U26: 0 | V26: 0 | W26: =SUM(C26:V26)
A27: W09 | B27: =IF('SWOT Weighted Assessment'!B29<>"", 'SWOT Weighted Assessment'!B29, "W09 [Disponible]") | C27: 0 | D27: 0 | E27: 0 | F27: 0 | G27: 0 | H27: 0 | I27: 0 | J27: 0 | K27: 0 | L27: 0 | M27: 0 | N27: 0 | O27: 0 | P27: 0 | Q27: 0 | R27: 0 | S27: 0 | T27: 0 | U27: 0 | V27: 0 | W27: =SUM(C27:V27)
A28: W10 | B28: =IF('SWOT Weighted Assessment'!B30<>"", 'SWOT Weighted Assessment'!B30, "W10 [Disponible]") | C28: 0 | D28: 0 | E28: 0 | F28: 0 | G28: 0 | H28: 0 | I28: 0 | J28: 0 | K28: 0 | L28: 0 | M28: 0 | N28: 0 | O28: 0 | P28: 0 | Q28: 0 | R28: 0 | S28: 0 | T28: 0 | U28: 0 | V28: 0 | W28: =SUM(C28:V28)
B29: Column Total | C29: =SUM(C8:C17)+SUM(C19:C28) | D29: =SUM(D8:D17)+SUM(D19:D28) | E29: =SUM(E8:E17)+SUM(E19:E28) | F29: =SUM(F8:F17)+SUM(F19:F28) | G29: =SUM(G8:G17)+SUM(G19:G28) | H29: =SUM(H8:H17)+SUM(H19:H28) | I29: =SUM(I8:I17)+SUM(I19:I28) | J29: =SUM(J8:J17)+SUM(J19:J28) | ... W29: =SUM(W8:W17)+SUM(W19:W28)
B31: Total Offensive Synergy (S x O) | H31: Total Defensive Moat (S x T) | N31: Turnaround Friction (W x O) | T31: Critical Vulnerability (W x T)
B32: =SUM(C8:L17) | H32: =SUM(M8:V17) | N32: =SUM(C19:L28) | T32: =SUM(M19:V28)

Sheet Action Plan (SO, WO, ST, WT)
A2: DATALARIA | C-LEVEL STRATEGIC ACTION ROADMAP (TOWS / CAME)
A3: Operational translation of the strategic decision matrix into capital allocation initiatives with C-Level ownership, timeline, and P&L targets.
A5: 1. WEAKNESS MITIGATION / TURNAROUND (WO Strategies)
A6: Action ID | B6: Key Factor | C6: Strategic Initiative & Scope | D6: C-Level Owner | E6: Target | F6: CAPEX (€) | G6: OPEX (€) | H6: P&L Target Metric / KPI | I6: Approval
A7: TOWS-W01 | B7: W01 + O03 | C7: Commercial Diversification Program: Launch LatAm channel to compress top-client concentration below 25% | D7: Chief Commercial Officer | E7: Q2-Q4 | F7: 45000 | G7: 60000 | H7: Top-2 revenue concentration < 25% | I7: Approved
A8: TOWS-W02 | B8: W02 + O05 | C8: Enterprise Sales Cycle Automation: Tier-1 SI co-selling framework to reduce deal velocity to 5 months | D8: VP Sales Enterprise | E8: Q1-Q3 | F8: 25000 | G8: 35000 | H8: Average cycle time ≤ 5.2 months | I8: Approved
A9: TOWS-W03 | B9: W05 + O02 | C9: Legacy Billing Refactor: Modernize multi-currency engine to cloud-native microservices | D9: Chief Technology Officer | E9: Q2-Q3 | F9: 40000 | G9: 15000 | H9: Maintenance debt < 6% capacity | I9: In Review
A10: SECTION TOTAL INVESTMENT (C) | F10: =SUM(F7:F9) | G10: =SUM(G7:G9)
A12: 2. THREAT DEFENSE & RISK HEDGING (ST Strategies)
A13: Action ID | B13: Key Factor | C13: Strategic Initiative & Scope | D13: C-Level Owner | E13: Target | F13: CAPEX (€) | G13: OPEX (€) | H13: P&L Target Metric / KPI | I13: Approval
A14: TOWS-T01 | B14: S01 + T01 | C14: Multi-Year Contract Lock-in: Secure 3-year master agreements with top accounts to defeat Asian discount pricing | D14: Chief Executive Officer | E14: Q1-Q2 | F14: 10000 | G14: 20000 | H14: Net ARR churn < 1.5% | I14: Approved
A15: TOWS-T02 | B15: S04 + T05 | C15: Accelerated NIS2 & DORA Compliance: Execute pre-audit readiness for enterprise supply chain mandates | D15: Chief Information Security Officer | E15: Q2-Q3 | F15: 35000 | G15: 15000 | H15: 100% regulatory audit pass | I15: Approved
A16: SECTION TOTAL INVESTMENT (A) | F16: =SUM(F14:F15) | G16: =SUM(G14:G15)
A18: 3. STRENGTH PRESERVATION & MOAT EXPANSION (Competitive Defense)
A19: Action ID | B19: Key Factor | C19: Strategic Initiative & Scope | D19: C-Level Owner | E19: Target | F19: CAPEX (€) | G19: OPEX (€) | H19: P&L Target Metric / KPI | I19: Approval
A20: TOWS-S01 | B20: S02 + O02 | C20: IP Moat Expansion: File supplemental patent claims in US/Asia for core predictive neural architecture | D20: Head of Legal & IP | E20: Q3-Q4 | F20: 30000 | G20: 10000 | H20: 2 supplemental patents granted | I20: Proposed
A21: TOWS-S02 | B21: S05 + T02 | C21: Senior R&D Retention Moat: Deploy LTIP / Phantom Equity incentive package to retain top AI engineers | D21: Chief People Officer | E21: Q1-Q4 | F21: 0 | G21: 45000 | H21: Voluntary engineering churn < 3% | I21: Approved
A22: SECTION TOTAL INVESTMENT (M) | F22: =SUM(F20:F21) | G22: =SUM(G20:G21)
A24: 4. OPPORTUNITY CAPTURE & AGGRESSIVE GROWTH (SO Strategies)
A25: Action ID | B25: Key Factor | C25: Strategic Initiative & Scope | D25: C-Level Owner | E25: Target | F25: CAPEX (€) | G25: OPEX (€) | H25: P&L Target Metric / KPI | I25: Approval
A26: TOWS-O01 | B26: S01 + O01 | C26: Industrial SaaS Scaling: Deploy subsidy-backed smart manufacturing module across 40 manufacturing sites | D26: Chief Operating Officer | E26: Q1-Q3 | F26: 65000 | G26: 40000 | H26: +€1.2M incremental ARR | I26: Approved
A27: TOWS-O02 | B27: S03 + O05 | C27: Tier-1 SI Joint Go-to-Market: Embed proprietary engine into global systems integrator enterprise catalog | D27: Chief Commercial Officer | E27: Q2-Q4 | F27: 20000 | G27: 30000 | H27: +8 new Fortune 500 logos | I27: Approved
A28: SECTION TOTAL INVESTMENT (E) | F28: =SUM(F26:F27) | G28: =SUM(G26:G27)
A30: TOTAL STRATEGIC BUDGET REQUIRED (CAPEX + OPEX) | F30: =F10+F16+F22+F28 | G30: =G10+G16+G22+G28 | H30: =F30+G30
